Workbook

Sheet Sheet1
A2: 1 | C2: 61674-BZ020 | D2: FINISH GOODS
A3: 2 | C3: 61673-BZ020 | D3: FINISH GOODS
A4: 3 | C4: 13-10681-A09 | D4: FINISH GOODS
A5: 4 | C5: GA241-06980 | D5: FINISH GOODS
A6: 5 | C6: 61642-VT020 | D6: FINISH GOODS
A7: 6 | C7: GA251-24260 | D7: FINISH GOODS
A8: 7 | C8: 57184-BZ030 | D8: FINISH GOODS
A9: 8 | C9: 57183-BZ020 | D9: FINISH GOODS
A10: 9 | C10: 67391-KK010 | D10: FINISH GOODS
A11: 10 | C11: B121-97515 | D11: FINISH GOODS
A12: 11 | C12: 55114-VT020 | D12: FINISH GOODS
A13: 12 | C13: B121-97517 | D13: FINISH GOODS
... A17: 16 | C17: 57434-BZ020 | D17: FINISH GOODS
A18: 17 | B18: 61143-T86-K000-50 | C18: 61143-T86-K000-50 | D18: FINISH GOODS
A19: 18 | C19: B111-97510 | D19: FINISH GOODS
A20: 19 | C20: B113-97514 | D20: FINISH GOODS
A21: 20 | C21: 65325-T86-K000-50 | D21: FINISH GOODS
A22: 21 | C22: 64123-TG2-K000-H1 | D22: FINISH GOODS
A23: 22 | B23: 67168-0K020 | C23: 67168-0K020 | D23: FINISH GOODS
A24: 23 | B24: 67167-0K020 | C24: 67167-0K020 | D24: FINISH GOODS
A25: 24 | C25: B121-97514 | D25: FINISH GOODS
A26: 25 | C26: B114-97515 | D26: FINISH GOODS
A27: 26 | C27: B111-97511 | D27: FINISH GOODS
A28: 27 | C28: 51321-BZ100 | D28: FINISH GOODS
A29: 28 | C29: 65325-T86-X000-50 | D29: FINISH GOODS
A30: 29 | C30: 61143-T86-X000-50 | D30: FINISH GOODS
A31: 30 | C31: B121-97512 | D31: FINISH GOODS
A32: 31 | C32: B114-97512 | D32: FINISH GOODS
A33: 32 | C33: B111-97505 | D33: FINISH GOODS
A34: 33 | C34: B122-97505 | D34: FINISH GOODS
A35: 34 | C35: 33146-0K060 | D35: FINISH GOODS
A36: 35 | C36: B121-97518 | D36: FINISH GOODS
... A40: 39 | C40: B122-97504 | D40: FINISH GOODS
A41: 40 | B41: B121-97513 | C41: B121-97513 | D41: FINISH GOODS
A42: 41 | B42: 51321-BZ110 | C42: 51321-BZ110 | D42: FINISH GOODS

Sheet 1
B1: List Part : Line Store "Finish Goods"
B2: NO | C2: PART NO | D2: CUSTOMER | E2: CYCLE ISSUE | F2: DEL/DAY | G2: Order Terbanyak percycle | H2: CYCLE
H3: C1 | I3: C2 | J3: C3 | K3: C4 | L3: C5 | M3: C6 | N3: C7 | O3: C8 | P3: C9 | Q3: C10
B4: 3 | C4: 57183-BZ020 | D4: ADM | E4: 1-2-X | F4: 12 | G4: 7 | H4: 0.29166667 | I4: 0.79166667
B5: 4 | C5: 57184-BZ030 | D5: ADM | E5: 1-2-X | F5: 12 | G5: 7 | H5: 0.29166667 | I5: 0.79166667
B6: 5 | C6: 51321-BZ100 | D6: ADM | E6: 1-2-X | F6: 7 | G6: 9 | H6: 0.29166667 | I6: 0.79166667
B7: 23 | C7: 57183-BZ010 | D7: GM | E7: 1-2-X | F7: 4 | G7: 3 | H7: 0.33333333 | I7: 0.83333333
B8: 24 | C8: 57433-BZ020 | D8: GM | E8: 1-2-X | F8: 4 | G8: 3 | H8: 0.33333333 | I8: 0.83333333
B9: 25 | C9: 57184-BZ020 | D9: GM | E9: 1-2-X | F9: 4 | G9: 3 | H9: 0.33333333 | I9: 0.83333333
B10: 26 | C10: 57434-BZ020 | D10: GM | E10: 1-2-X | F10: 4 | G10: 3 | H10: 0.33333333 | I10: 0.83333333
B11: 32 | C11: JJB03-001530 | D11: JTEKT | E11: 1-2-X | F11: 1 | G11: 8 | H11: 0.125 | I11: 0.625
B12: 33 | C12: 55114-VT020 | D12: NTC | E12: 1-2-X | F12: 9 | G12: 6 | H12: 0.33333333 | I12: 0.83333333
B13: 34 | C13: 61642-VT020 | D13: NTC | E13: 1-2-X | F13: 15 | G13: 8 | H13: 0.33333333 | I13: 0.83333333
B14: 6 | C14: B113-97514 | D14: F.SEAT | E14: 1-4-X | F14: 4 | G14: 6 | H14: 0.041666667 | I14: 0.16666667 | J14: 0.58333333 | K14: 0.75
B15: 7 | C15: B111-97510 | D15: F.SEAT | E15: 1-4-X | F15: 4 | G15: 5 | H15: 0.041666667 | I15: 0.16666667 | J15: 0.58333333 | K15: 0.75
B16: 8 | C16: B122-97505 | D16: F.SEAT | E16: 1-4-X | F16: 4 | G16: 6 | H16: 0.041666667 | I16: 0.16666667 | J16: 0.58333333 | K16: 0.75
B17: 9 | C17: B121-97514 | D17: F.SEAT | E17: 1-4-X | F17: 7 | G17: 8 | H17: 0.041666667 | I17: 0.16666667 | J17: 0.58333333 | K17: 0.75
B18: 10 | C18: B121-97512 | D18: F.SEAT | E18: 1-4-X | F18: 6 | G18: 7 | H18: 0.041666667 | I18: 0.16666667 | J18: 0.58333333 | K18: 0.75
B19: 11 | C19: B114-97515 | D19: F.SEAT | E19: 1-4-X | F19: 3 | G19: 6 | H19: 0.041666667 | I19: 0.16666667 | J19: 0.58333333 | K19: 0.75
B20: 12 | C20: B121-97515 | D20: F.SEAT | E20: 1-4-X | F20: 5 | G20: 6 | H20: 0.041666667 | I20: 0.16666667 | J20: 0.58333333 | K20: 0.75
B21: 13 | C21: B111-97511 | D21: F.SEAT | E21: 1-4-X | F21: 3 | G21: 6 | H21: 0.041666667 | I21: 0.16666667 | J21: 0.58333333 | K21: 0.75
B22: 14 | C22: B121-97517 | D22: F.SEAT | E22: 1-4-X | F22: 2 | G22: 2 | H22: 0.041666667 | I22: 0.16666667 | J22: 0.58333333 | K22: 0.75
B23: 15 | C23: B111-97505 | D23: F.SEAT | E23: 1-4-X | F23: 2 | G23: 3 | H23: 0.041666667 | I23: 0.16666667 | J23: 0.58333333 | K23: 0.75
B24: 16 | C24: B114-97512 | D24: F.SEAT | E24: 1-4-X | F24: 2 | G24: 3 | H24: 0.041666667 | I24: 0.16666667 | J24: 0.58333333 | K24: 0.75
B25: 17 | C25: B122-97504 | D25: F.SEAT | E25: 1-4-X | F25: 1 | G25: 1 | H25: 0.041666667 | I25: 0.16666667 | J25: 0.58333333 | K25: 0.75
... B29: 21 | C29: B121-97511 | D29: F.SEAT | E29: 1-4-X | F29: 1 | G29: 1 | H29: 0.041666667 | I29: 0.16666667 | J29: 0.58333333 | K29: 0.75
B30: 1 | C30: 61673-BZ020 | D30: ADM/TMN | E30: 1-5-x | F30: 40 | G30: 15 | H30: 0.21180556 | I30: 0.37708333 | J30: 0.49375 | K30: 0.71666667 | L30: 0.99236111
B31: 2 | C31: 61674-BZ020 | D31: ADM/TMN | E31: 1-5-x | F31: 40 | G31: 15 | H31: 0.21180556 | I31: 0.37708333 | J31: 0.49375 | K31: 0.71666667 | L31: 0.99236111
B32: 37 | C32: 67391-KK010 | D32: TMMIN | E32: 1-5-X | F32: 10 | G32: 3 | H32: 0.11041667 | I32: 0.26805556 | J32: 0.43472222 | K32: 0.75069444 | L32: 0.90208333
B33: 38 | C33: 33146-0K060 | D33: TMMIN | E33: 1-10-X | F33: 2 | G33: 1 | H33: 0.25972222 | I33: 0.33611111 | J33: 0.39930556 | K33: 0.48888889 | L33: 0.56597222 | M33: 0.62222222 | N33: 0.83125 | O33: 0.90902778 | P33: 0.032638889 | Q33: 0.11111111
B34: 22 | C34: 13-10681-A09 | D34: FTR | E34: 1-1-X | F34: 13 | G34: 16 | H34: 0.33333333
B35: 27 | C35: 64123-TG2-K000-H1 | D35: GTIM | E35: 1-1-X | F35: 4 | G35: 8 | H35: 0.45833333
B36: 28 | C36: 65325-T86-K000-50 | D36: GTIM | E36: 1-1-X | F36: 7 | G36: 9 | H36: 0.45833333
B37: 29 | C37: 65325-T86-X000-50 | D37: GTIM | E37: 1-1-X | F37: 4 | G37: 9 | H37: 0.45833333
B38: 30 | C38: 61143-T86-X000-50 | D38: GTIM | E38: 1-1-X | F38: 0 | G38: 0 | H38: 0.45833333
B39: 31 | C39: 61143-T86-K000-50 | D39: GTIM | E39: 1-1-X | F39: 2 | G39: 2 | H39: 0.45833333
B40: 35 | C40: GA241-06980 | D40: TGIDN | E40: 1-1-X | F40: 15 | G40: 20 | H40: 0.33333333
B41: 36 | C41: GA251-24260 | D41: TGIDN | E41: 1-1-X | F41: 6 | G41: 7 | H41: 0.33333333

Sheet Heijunka Tandem 9 ke FG
F1: 0.29166667 | G1: 0.0069444444 | J1: 0.020833333 | M1: 0.0069444444 | R1: 0.03125 | W1: 0.0069444444 | Z1: 0.66666667 | AH1: 0.83680556 | AI1: =J1 -> 0.020833333 | AP1: 0.027777778 | AV1: 0.027777778 | AX1: 0.20833333
B3: CYCLE ISSUE | C3: Kbn per Cycle | D3: cycle per day | E3: cycle shift | F3: cycle shift (bulat)
G4: =F1+G1 -> 0.29861111 | H4: =G4+$J1 -> 0.31944444 | I4: =H4+$J1 -> 0.34027778 | J4: =I4+$J1 -> 0.36111111 | K4: =J4+$J1 -> 0.38194444 | L4: =K4+$J1 -> 0.40277778 | N4: =L4+$J1+M1 -> 0.43055556 | O4: =N4+$J1 -> 0.45138889 | P4: =O4+$J1 -> 0.47222222 | Q4: =P4+$J1 -> 0.49305556 | S4: =Q4+$J1+R1 -> 0.54513889 | T4: =S4+$J1 -> 0.56597222 | U4: =T4+$J1 -> 0.58680556 | V4: =U4+$J1 -> 0.60763889 | X4: =V4+$J1+W1 -> 0.63541667 | Y4: =X4+$J1 -> 0.65625 | Z4: =Y4+$J1 -> 0.67708333 | AA4: =Z4+$J1 -> 0.69791667 | AB4: =AA4+$J1 -> 0.71875 | AC4: =AB4+$J1 -> 0.73958333 | AH4: =AH1 -> 0.83680556 | AI4: =AH4+$AI1 -> 0.85763889 | AJ4: =AI4+$AI1 -> 0.87847222 | AK4: =AJ4+$AI1 -> 0.89930556 | AL4: =AK4+$AI1 -> 0.92013889 | AM4: =AL4+$AI1 -> 0.94097222 | AN4: =AM4+$AI1 -> 0.96180556 | AO4: =AN4+$AI1 -> 0.98263889 | AQ4: =AO4+$AI1+AP1 -> 1.03125 | AR4: =AQ4+$AI1 -> 1.0520833 | AS4: =AR4+$AI1 -> 1.0729167 | AT4: =AS4+$AI1 -> 1.09375 | AU4: =AT4+$AI1 -> 1.1145833 | AW4: =AU4+$AI1+AV1 -> 1.1631944 | AX4: =AW4+$AI1 -> 1.1840278 | AY4: =AX4+$AI1 -> 1.2048611 | AZ4: =AY4+$J1 -> 1.2256944
G5: 1 | H5: 2 | I5: 3 | J5: 4 | K5: 5 | L5: 6 | N5: 7 | O5: 8 | P5: 9 | Q5: 10 | S5: 11 | T5: 12 | U5: 13 | V5: 14 | X5: 15 | Y5: 16 | AH5: 17 | AI5: 18 | AJ5: 19 | AK5: 20 | AL5: 21 | AM5: 22 | AN5: 23 | AO5: 24 | AQ5: 25 | AR5: 26 | AS5: 27 | AT5: 28 | AU5: 29 | AW5: 30 | AX5: 31 | AY5: 32
C7: RANDOM NUMBER --> | G7: 1 | H7: 9 | I7: 5 | J7: 13 | K7: 3 | L7: 11 | N7: 7 | O7: 15 | P7: 2 | Q7: 10 | S7: 6 | T7: 14 | U7: 4 | V7: 12 | X7: 8 | Y7: 16 | AH7: 1 | AI7: 9 | AJ7: 5 | AK7: 13 | AL7: 3 | AM7: 11 | AN7: 7 | AO7: 15 | AQ7: 2 | AR7: 10 | AS7: 6 | AT7: 14 | AU7: 4 | AW7: 12 | AX7: 8 | AY7: 16
B8: 1-2-X | D8: =32 -> 32 | E8: =32/2 -> 16 | F8: =32/2 -> 16 | G8: Cyc-1 | AH8: Cyc-2
A9: 1 | B9: ='1'!C4 -> 57183-BZ020 | C9: ='1'!G4 -> 7 | G9: 1 | I9: 1 | K9: 1 | N9: 1 | P9: 1 | S9: 1 | U9: 1 | Z9: =SUM(G9:Y9) -> 7 | AH9: 1 | AJ9: 1 | AL9: 1 | AN9: 1 | AQ9: 1 | AS9: 1 | AU9: 1
A10: 2 | B10: ='1'!C5 -> 57184-BZ030 | C10: ='1'!G5 -> 7 | H10: 1 | J10: 1 | L10: 1 | Q10: 1 | T10: 1 | V10: 1 | X10: 1 | Z10: =SUM(G10:Y10) -> 7 | AI10: 1 | AK10: 1 | AM10: 1 | AR10: 1 | AT10: 1 | AW10: 1 | AX10: 1
A11: 3 | B11: ='1'!C6 -> 51321-BZ100 | C11: ='1'!G6 -> 9 | G11: 1 | I11: 1 | K11: 1 | N11: 1 | O11: 1 | P11: 1 | S11: 1 | U11: 1 | Y11: 1 | Z11: =SUM(G11:Y11) -> 9 | AH11: 1 | AJ11: 1 | AL11: 1 | AN11: 1 | AO11: 1 | AQ11: 1 | AS11: 1 | AU11: 1 | AY11: 1
A12: 4 | B12: ='1'!C7 -> 57183-BZ010 | C12: ='1'!G7 -> 3 | H12: 1 | Q12: 1 | X12: 1 | Z12: =SUM(G12:Y12) -> 3 | AI12: 1 | AR12: 1 | AX12: 1
A13: 5 | B13: ='1'!C8 -> 57433-BZ020 | C13: ='1'!G8 -> 3 | J13: 1 | L13: 1 | V13: 1 | Z13: =SUM(G13:Y13) -> 3 | AK13: 1 | AM13: 1 | AW13: 1
A14: 6 | B14: ='1'!C9 -> 57184-BZ020 | C14: ='1'!G9 -> 3 | O14: 1 | T14: 1 | Y14: 1 | Z14: =SUM(G14:Y14) -> 3 | AO14: 1 | AT14: 1 | AY14: 1
A15: 7 | B15: ='1'!C10 -> 57434-BZ020 | C15: ='1'!G10 -> 3 | G15: 1 | K15: 1 | P15: 1 | Z15: =SUM(G15:Y15) -> 3 | AH15: 1 | AL15: 1 | AQ15: 1
A16: 8 | B16: ='1'!C11 -> JJB03-001530 | C16: ='1'!G11 -> 8 | H16: 1 | I16: 1 | L16: 1 | N16: 1 | Q16: 1 | S16: 1 | U16: 1 | X16: 1 | Z16: =SUM(G16:Y16) -> 8 | AI16: 1 | AJ16: 1 | AM16: 1 | AN16: 1 | AR16: 1 | AS16: 1 | AU16: 1 | AX16: 1
A17: 9 | B17: ='1'!C12 -> 55114-VT020 | C17: ='1'!G12 -> 6 | G17: 1 | J17: 1 | O17: 1 | T17: 1 | V17: 1 | Y17: 1 | Z17: =SUM(G17:Y17) -> 6 | AH17: 1 | AK17: 1 | AO17: 1 | AT17: 1 | AW17: 1 | AY17: 1
A18: 10 | B18: ='1'!C13 -> 61642-VT020 | C18: ='1'!G13 -> 8 | H18: 1 | I18: 1 | K18: 1 | N18: 1 | P18: 1 | S18: 1 | U18: 1 | X18: 1 | Z18: =SUM(G18:Y18) -> 8 | AI18: 1 | AJ18: 1 | AL18: 1 | AN18: 1 | AQ18: 1 | AS18: 1 | AU18: 1 | AX18: 1
C19: SUB. TOTAL KBN | G19: =SUM(G9:G18) -> 4 | H19: =SUM(H9:H18) -> 4 | I19: =SUM(I9:I18) -> 4 | J19: =SUM(J9:J18) -> 3 | K19: =SUM(K9:K18) -> 4 | L19: =SUM(L9:L18) -> 3 | M19: =SUM(M9:M18) -> 0 | N19: =SUM(N9:N18) -> 4 | ... Y19: =SUM(Y9:Y18) -> 3 | AH19: =SUM(AH9:AH18) -> 4 | AI19: =SUM(AI9:AI18) -> 4 | AJ19: =SUM(AJ9:AJ18) -> 4 | AK19: =SUM(AK9:AK18) -> 3 | AL19: =SUM(AL9:AL18) -> 4 | AM19: =SUM(AM9:AM18) -> 3 | AN19: =SUM(AN9:AN18) -> 4 | AO19: =SUM(AO9:AO18) -> 3 | ... AY19: =SUM(AY9:AY18) -> 3
G20: 1 | H20: 5 | I20: 3 | J20: 7 | K20: 2 | L20: 6 | N20: 4 | O20: 8 | P20: 1 | Q20: 5 | S20: 3 | T20: 7 | U20: 2 | V20: 6 | X20: 4 | Y20: 8 | AH20: 1 | AI20: 5 | AJ20: 3 | AK20: 7 | AL20: 2 | AM20: 6 | AN20: 4 | AO20: 8 | AQ20: 1 | AR20: 5 | AS20: 3 | AT20: 7 | AU20: 2 | AW20: 6 | AX20: 4 | AY20: 8
B21: 1-4-X | D21: =32 -> 32 | E21: =32/4 -> 8 | F21: =32/4 -> 8 | G21: Cyc-1 | P21: Cyc-2 | AH21: Cyc-3 | AQ21: Cyc-4
A22: 1 | B22: ='1'!C14 -> B113-97514 | C22: ='1'!G14 -> 6 | G22: 1 | H22: 1 | I22: 1 | K22: 1 | L22: 1 | N22: 1 | P22: 1 | Q22: 1 | S22: 1 | U22: 1 | V22: 1 | X22: 1 | Z22: =SUM(G22:Y22) -> 12 | AH22: 1 | AI22: 1 | AJ22: 1 | AL22: 1 | AM22: 1 | AN22: 1 | AQ22: 1 | AR22: 1 | AS22: 1 | AU22: 1 | AW22: 1 | AX22: 1
A23: 2 | B23: ='1'!C15 -> B111-97510 | C23: ='1'!G15 -> 5 | G23: 1 | I23: 1 | J23: 1 | K23: 1 | O23: 1 | P23: 1 | S23: 1 | T23: 1 | U23: 1 | Y23: 1 | Z23: =SUM(G23:Y23) -> 10 | AH23: 1 | AJ23: 1 | AK23: 1 | AL23: 1 | AO23: 1 | AQ23: 1 | AS23: 1 | AT23: 1 | AU23: 1 | AY23: 1
A24: 3 | B24: ='1'!C16 -> B122-97505 | C24: ='1'!G16 -> 6 | G24: 1 | H24: 1 | J24: 1 | L24: 1 | N24: 1 | O24: 1 | P24: 1 | Q24: 1 | T24: 1 | V24: 1 | X24: 1 | Y24: 1 | Z24: =SUM(G24:Y24) -> 12 | AH24: 1 | AI24: 1 | AK24: 1 | AM24: 1 | AN24: 1 | AO24: 1 | AQ24: 1 | AR24: 1 | AT24: 1 | AW24: 1 | AX24: 1 | AY24: 1
A25: 4 | B25: ='1'!C17 -> B121-97514 | C25: ='1'!G17 -> 8 | G25: 1 | H25: 1 | I25: 1 | J25: 1 | K25: 1 | L25: 1 | N25: 1 | O25: 1 | P25: 1 | Q25: 1 | S25: 1 | T25: 1 | U25: 1 | V25: 1 | X25: 1 | Y25: 1 | Z25: =SUM(G25:Y25) -> 16 | AH25: 1 | AI25: 1 | AJ25: 1 | AK25: 1 | AL25: 1 | AM25: 1 | AN25: 1 | AO25: 1 | AQ25: 1 | AR25: 1 | AS25: 1 | AT25: 1 | AU25: 1 | AW25: 1 | AX25: 1 | AY25: 1
A26: 5 | B26: ='1'!C18 -> B121-97512 | C26: ='1'!G18 -> 7 | H26: 1 | I26: 1 | J26: 1 | K26: 1 | L26: 1 | N26: 1 | O26: 1 | Q26: 1 | S26: 1 | T26: 1 | U26: 1 | V26: 1 | X26: 1 | Y26: 1 | Z26: =SUM(G26:Y26) -> 14 | AI26: 1 | AJ26: 1 | AK26: 1 | AL26: 1 | AM26: 1 | AN26: 1 | AO26: 1 | AR26: 1 | AS26: 1 | AT26: 1 | AU26: 1 | AW26: 1 | AX26: 1 | AY26: 1
A27: 6 | B27: ='1'!C19 -> B114-97515 | C27: ='1'!G19 -> 6 | G27: 1 | H27: 1 | I27: 1 | K27: 1 | L27: 1 | N27: 1 | P27: 1 | Q27: 1 | S27: 1 | U27: 1 | V27: 1 | X27: 1 | Z27: =SUM(G27:Y27) -> 12 | AH27: 1 | AI27: 1 | AJ27: 1 | AL27: 1 | AM27: 1 | AN27: 1 | AQ27: 1 | AR27: 1 | AS27: 1 | AU27: 1 | AW27: 1 | AX27: 1
A28: 7 | B28: ='1'!C20 -> B121-97515 | C28: ='1'!G20 -> 6 | G28: 1 | I28: 1 | J28: 1 | K28: 1 | N28: 1 | O28: 1 | P28: 1 | S28: 1 | T28: 1 | U28: 1 | X28: 1 | Y28: 1 | Z28: =SUM(G28:Y28) -> 12 | AH28: 1 | AJ28: 1 | AK28: 1 | AL28: 1 | AN28: 1 | AO28: 1 | AQ28: 1 | AS28: 1 | AT28: 1 | AU28: 1 | AX28: 1 | AY28: 1
A29: 8 | B29: ='1'!C21 -> B111-97511 | C29: ='1'!G21 -> 6 | G29: 1 | H29: 1 | J29: 1 | K29: 1 | L29: 1 | O29: 1 | P29: 1 | Q29: 1 | T29: 1 | U29: 1 | V29: 1 | Y29: 1 | Z29: =SUM(G29:Y29) -> 12 | AH29: 1 | AI29: 1 | AK29: 1 | AL29: 1 | AM29: 1 | AO29: 1 | AQ29: 1 | AR29: 1 | AT29: 1 | AU29: 1 | AW29: 1 | AY29: 1
A30: 9 | B30: ='1'!C22 -> B121-97517 | C30: ='1'!G22 -> 2 | I30: 1 | N30: 1 | S30: 1 | X30: 1 | Z30: =SUM(G30:Y30) -> 4 | AJ30: 1 | AN30: 1 | AS30: 1 | AX30: 1
A31: 10 | B31: ='1'!C23 -> B111-97505 | C31: ='1'!G23 -> 3 | H31: 1 | J31: 1 | L31: 1 | Q31: 1 | T31: 1 | V31: 1 | Z31: =SUM(G31:Y31) -> 6 | AI31: 1 | AK31: 1 | AM31: 1 | AR31: 1 | AT31: 1 | AW31: 1
A32: 11 | B32: ='1'!C24 -> B114-97512 | C32: ='1'!G24 -> 3 | G32: 1 | K32: 1 | O32: 1 | P32: 1 | U32: 1 | Y32: 1 | Z32: =SUM(G32:Y32) -> 6 | AH32: 1 | AL32: 1 | AO32: 1 | AQ32: 1 | AU32: 1 | AY32: 1
A33: 12 | B33: ='1'!C25 -> B122-97504 | C33: ='1'!G25 -> 1 | N33: 1 | X33: 1 | Z33: =SUM(G33:Y33) -> 2 | AN33: 1 | AX33: 1
A34: 13 | B34: ='1'!C26 -> B121-97518 | C34: ='1'!G26 -> 1 | H34: 1 | Q34: 1 | Z34: =SUM(G34:Y34) -> 2 | AI34: 1 | AR34: 1
A35: 14 | B35: ='1'!C27 -> B111-97502 | C35: ='1'!G27 -> 1 | L35: 1 | V35: 1 | Z35: =SUM(G35:Y35) -> 2 | AM35: 1 | AW35: 1
A36: 15 | B36: ='1'!C28 -> B114-97511 | C36: ='1'!G28 -> 1 | J36: 1 | T36: 1 | Z36: =SUM(G36:Y36) -> 2 | AK36: 1 | AT36: 1
A37: 16 | B37: ='1'!C29 -> B121-97511 | C37: ='1'!G29 -> 1 | O37: 1 | Y37: 1 | Z37: =SUM(G37:Y37) -> 2 | AO37: 1 | AY37: 1
C38: SUB. TOTAL KBN | G38: =SUM(G22:G37) -> 8 | H38: =SUM(H22:H37) -> 8 | I38: =SUM(I22:I37) -> 7 | J38: =SUM(J22:J37) -> 8 | K38: =SUM(K22:K37) -> 8 | L38: =SUM(L22:L37) -> 8 | M38: =SUM(M22:M37) -> 0 | N38: =SUM(N22:N37) -> 8 | ... Y38: =SUM(Y22:Y37) -> 8 | AH38: =SUM(AH22:AH37) -> 8 | AI38: =SUM(AI22:AI37) -> 8 | AJ38: =SUM(AJ22:AJ37) -> 7 | AK38: =SUM(AK22:AK37) -> 8 | AL38: =SUM(AL22:AL37) -> 8 | AM38: =SUM(AM22:AM37) -> 8 | AN38: =SUM(AN22:AN37) -> 8 | AO38: =SUM(AO22:AO37) -> 8 | ... AY38: =SUM(AY22:AY37) -> 8
G39: 1 | H39: 5 | I39: 3 | J39: 2 | K39: 6 | L39: 4 | N39: 1 | O39: 5 | P39: 3 | Q39: 2 | S39: 6 | T39: 4 | U39: 1 | V39: 5 | X39: 3 | AH39: 2 | AI39: 6 | AJ39: 4 | AK39: 1 | AL39: 5 | AM39: 3 | AN39: 2 | AO39: 6 | AQ39: 4 | AR39: 1 | AS39: 5 | AT39: 3 | AU39: 2 | AW39: 6 | AX39: 4
B40: 1-5-X | D40: =32 -> 32 | E40: =32/5 -> 6.4 | F40: 6 | G40: Cyc-1 | N40: Cyc-2 | U40: Cyc-3 | AH40: Cyc-3 | AK40: Cyc-4 | AR40: Cyc-5
A41: 1 | B41: ='1'!C30 -> 61673-BZ020 | C41: ='1'!G30 -> 15 | G41: 3 | H41: 2 | I41: 3 | J41: 3 | K41: 2 | L41: 2 | N41: 3 | O41: 2 | P41: 3 | Q41: 3 | S41: 2 | T41: 2 | U41: 3 | V41: 2 | X41: 3 | Z41: =SUM(G41:Y41) -> 38 | AH41: 3 | AI41: 2 | AJ41: 2 | AK41: 3 | AL41: 2 | AM41: 3 | AN41: 3 | AO41: 2 | AQ41: 2 | AR41: 3 | AS41: 2 | AT41: 3 | AU41: 3 | AW41: 2 | AX41: 2
A42: 2 | B42: ='1'!C31 -> 61674-BZ020 | C42: ='1'!G31 -> 15 | G42: 2 | H42: 3 | I42: 2 | J42: 2 | K42: 3 | L42: 3 | N42: 2 | O42: 3 | P42: 2 | Q42: 2 | S42: 3 | T42: 3 | U42: 2 | V42: 3 | X42: 2 | Z42: =SUM(G42:Y42) -> 37 | AH42: 2 | AI42: 3 | AJ42: 3 | AK42: 2 | AL42: 3 | AM42: 2 | AN42: 2 | AO42: 3 | AQ42: 3 | AR42: 2 | AS42: 3 | AT42: 2 | AU42: 2 | AW42: 3 | AX42: 3
...
